Workbook

Sheet pxyild
A1: {=_xll.BQL("['ZO283134 Corp'; 'ZO290323 Corp'; 'ZO305198 Corp'; 'ZO283163 Corp'; 'ZO283017 Corp'; 'ZO300955 Corp'; 'GT2 Govt'; 'GT10 Govt']", "yield(yield_type='convention'; pricing_source='BGN'; dates=range('2021-09-30';btoday()))")} -> #NAME?

Sheet dur
A1: {=_xll.BQL("['ZO283134 Corp'; 'ZO290323 Corp'; 'ZO305198 Corp'; 'ZO283163 Corp'; 'ZO283017 Corp'; 'ZO300955 Corp'; 'GT2 Govt'; 'GT10 Govt']", "duration(dates=range('2021-09-30';btoday()))")} -> #NAME?

Sheet cnxv
A1: {=_xll.BQL("['ZO283134 Corp'; 'ZO290323 Corp'; 'ZO305198 Corp'; 'ZO283163 Corp'; 'ZO283017 Corp'; 'ZO300955 Corp'; 'GT2 Govt'; 'GT10 Govt']", "convexity( dates=range('2021-09-30';btoday()))")} -> #NAME?

Sheet px
A1: DATES | B1: GD29 | C1: GD30 | D1: GD35 | E1: GD38 | F1: GD41 | G1: GD46 | H1: GT2 | I1: GT10
A2: 44469 | B2: 20.71533 | C2: 20.265026 | D2: 17.132712 | E2: 17.32903 | F2: 15.505405 | G2: 17.201962 | H2: 0.2794394 | I2: 1.489039
A3: 44470 | B3: 20.670825 | C3: 20.145659 | D3: 17.063179 | E3: 17.251757 | F3: 15.437648 | G3: 17.105874 | H3: 0.2657624 | I3: 1.46331
A4: 44473 | B4: 20.739817 | C4: 20.265268 | D4: 17.123974 | E4: 17.322466 | F4: 15.524177 | G4: 17.070623 | H4: 0.2796009 | I4: 1.480637
A5: 44474 | B5: 20.623095 | C5: 20.098109 | D5: 17.00298 | E5: 17.229111 | F5: 15.420036 | G5: 16.969527 | H5: 0.28755 | I5: 1.529233
A6: 44475 | B6: 20.543219 | C6: 20.016352 | D6: 16.965358 | E6: 17.170578 | F6: 15.402304 | G6: 16.890729 | H6: 0.2955227 | I6: 1.522354
A7: 44476 | B7: 20.501488 | C7: 20.009989 | D7: 16.944282 | E7: 17.164152 | F7: 15.380289 | G7: 16.873323 | H7: 0.3094701 | I7: 1.574683
A8: 44477 | B8: 20.620793 | C8: 20.204115 | D8: 17.084799 | E8: 17.289705 | F8: 15.504223 | G8: 17.067051 | H8: 0.3217717 | I8: 1.615311
A9: 44481 | B9: 20.899513 | C9: 20.436592 | D9: 17.251192 | E9: 17.499727 | F9: 15.631653 | G9: 17.198451 | H9: 0.3398601 | I9: 1.580349
A10: 44482 | B10: 20.950353 | C10: 20.529611 | D10: 17.287648 | E10: 17.51397 | F10: 15.731446 | G10: 17.243903 | H10: 0.3600098 | I10: 1.538518
A11: 44483 | B11: 20.918964 | C11: 20.467659 | D11: 17.267983 | E11: 17.456885 | F11: 15.65907 | G11: 17.223046 | H11: 0.3621693 | I11: 1.514217
A12: 44484 | B12: 20.995567 | C12: 20.598567 | D12: 17.351195 | E12: 17.551225 | F12: 15.749483 | G12: 17.313817 | H12: 0.3968987 | I12: 1.573771
A13: 44487 | B13: 21.274577 | C13: 20.899648 | D13: 17.548973 | E13: 17.754685 | F13: 15.933441 | G13: 17.533059 | H13: 0.4273986 | I13: 1.60367
... A1512: 46246 | B1512: 7.934255 | C1512: 7.8909762 | D1512: 9.4086662 | E1512: 9.2615 | F1512: 9.4232942 | G1512: 9.3618527 | H1512: 4.1843834 | I1512: 4.6618586

Sheet durval
A1: DATES | B1: ZO283134 Corp | C1: ZO290323 Corp | D1: ZO305198 Corp | E1: ZO283163 Corp | F1: ZO283017 Corp | G1: ZO300955 Corp | H1: GT2 Govt | I1: GT10 Govt
A2: 44469 | B2: 4.44957 | C2: 4.690851 | D2: 7.530655 | E2: 6.36213 | F2: 7.241406 | G2: 6.608138 | H2: 1.9 | I2: 8
A3: 44470 | B3: 4.448472 | C3: 4.693331 | D3: 7.545815 | E3: 6.372225 | F3: 7.259624 | G3: 6.61954 | H3: 1.9 | I3: 8
A4: 44473 | B4: 4.442652 | C4: 4.68463 | D4: 7.524181 | E4: 6.350395 | F4: 7.231305 | G4: 6.627315 | H4: 1.9 | I4: 8
A5: 44474 | B5: 4.450792 | C5: 4.695053 | D5: 7.551736 | E5: 6.375261 | F5: 7.269135 | G5: 6.657704 | H5: 1.9 | I5: 8
A6: 44475 | B6: 4.448024 | C6: 4.696037 | D6: 7.551599 | E6: 6.378621 | F6: 7.262405 | G6: 6.685522 | H6: 1.9 | I6: 8
A7: 44476 | B7: 4.441926 | C7: 4.685357 | D7: 7.545172 | E7: 6.370912 | F7: 7.252866 | G7: 6.655221 | H7: 1.9 | I7: 8
A8: 44477 | B8: 4.432304 | C8: 4.669314 | D8: 7.51128 | E8: 6.347312 | F8: 7.225239 | G8: 6.622144 | H8: 1.9 | I8: 8
A9: 44481 | B9: 4.416199 | C9: 4.655774 | D9: 7.484391 | E9: 6.311435 | F9: 7.181911 | G9: 6.57628 | H9: 1.9 | I9: 8
A10: 44482 | B10: 4.411212 | C10: 4.648395 | D10: 7.466938 | E10: 6.294741 | F10: 7.158123 | G10: 6.560765 | H10: 1.9 | I10: 8
A11: 44483 | B11: 4.402527 | C11: 4.640254 | D11: 7.464085 | E11: 6.292271 | F11: 7.158305 | G11: 6.559752 | H11: 1.9 | I11: 8
A12: 44484 | B12: 4.398756 | C12: 4.634544 | D12: 7.443593 | E12: 6.274948 | F12: 7.134649 | G12: 6.535242 | H12: 1.9 | I12: 8
A13: 44487 | B13: 4.384794 | C13: 4.614144 | D13: 7.40606 | E13: 6.244613 | F13: 7.095335 | G13: 6.488893 | H13: 1.9 | I13: 8
... A303: 44910 | B303: 2.8761443 | C303: 3.0394983 | D303: 5.6482822 | E303: 4.6511142 | F303: 5.4835775 | G303: 4.3580378 | H303: 1.9 | I303: 8
A304: 44911 | B304: 2.8825161 | C304: 3.0524522 | D304: 5.6807451 | E304: 4.6868579 | F304: 5.5240372 | G304: #N/A | H304: 1.9 | I304: 8
A305: 44914 | B305: 2.8854476 | C305: 3.0693811 | D305: 5.7176658 | E305: 4.7052019 | F305: 5.5476526 | G305: #N/A | H305: 1.9 | I305: 8
A306: 44915 | B306: 2.8988497 | C306: 3.0741227 | D306: 5.7286506 | E306: 4.7257617 | F306: 5.554359 | G306: #N/A | H306: 1.9 | I306: 8
A307: 44916 | B307: 2.9038502 | C307: 3.0940125 | D307: 5.7682032 | E307: 4.7571486 | F307: 5.6012696 | G307: #N/A | H307: 1.9 | I307: 8
A308: 44917 | B308: 2.8876728 | C308: 3.0625536 | D308: 5.7300653 | E308: 4.7345042 | F308: 5.5724605 | G308: #N/A | H308: 1.9 | I308: 8
A309: 44918 | B309: 2.8677251 | C309: 3.0140503 | D309: 5.6870622 | E309: 4.6781476 | F309: 5.4995875 | G309: #N/A | H309: 1.9 | I309: 8
A310: 44922 | B310: 2.8501344 | C310: 3.0135975 | D310: 5.6618988 | E310: 4.6680615 | F310: 5.4855419 | G310: #N/A | H310: 1.9 | I310: 8
A311: 44923 | B311: 2.850054 | C311: 3.0104153 | D311: 5.6579355 | E311: 4.6707374 | F311: 5.4691161 | G311: #N/A | H311: 1.9 | I311: 8
A312: 44924 | B312: 2.8321378 | C312: 2.980668 | D312: 5.6286605 | E312: 4.6569191 | F312: 5.4473031 | G312: #N/A | H312: 1.9 | I312: 8
A313: 44925 | B313: 2.8166629 | C313: 2.9676386 | D313: 5.5986868 | E313: 4.6352794 | F313: 5.3962849 | G313: #N/A | H313: 1.9 | I313: 8
A314: 44929 | B314: 2.8299345 | C314: 2.9918778 | D314: 5.6470247 | E314: 4.6851862 | F314: 5.4660129 | G314: #N/A | H314: 1.9 | I314: 8
A315: 44930 | B315: 2.8543094 | C315: 3.0371686 | D315: 5.7218001 | E315: 4.7436648 | F315: 5.5776594 | G315: #N/A | H315: 1.9 | I315: 8
... A355: 44988 | B355: 2.770756 | C355: 2.9220771 | D355: 5.6415137 | E355: 4.8604571 | F355: 5.7129465 | G355: #N/A | H355: 1.9 | I355: 8
A356: 44991 | B356: 2.7795686 | C356: 2.9504461 | D356: 5.6957746 | E356: 4.9086978 | F356: 5.7754385 | G356: 4.4661225 | H356: 1.9 | I356: 8
A357: 44992 | B357: 2.7711199 | C357: 2.9334402 | D357: 5.6618392 | E357: 4.8818253 | F357: 5.744494 | G357: 4.4246831 | H357: 1.9 | I357: 8
A358: 44993 | B358: 2.746304 | C358: 2.9077167 | D358: 5.6044404 | E358: 4.8233511 | F358: 5.6668519 | G358: 4.3569688 | H358: 1.9 | I358: 8
A359: 44994 | B359: 2.7350931 | C359: 2.8904183 | D359: 5.5644275 | E359: 4.7776234 | F359: 5.6236234 | G359: 4.2996998 | H359: 1.9 | I359: 8
A360: 44995 | B360: 2.6847671 | C360: 2.826164 | D360: 5.4506209 | E360: 4.6802709 | F360: 5.4771483 | G360: 4.1634901 | H360: 1.9 | I360: 8
A361: 44998 | B361: 2.6731618 | C361: 2.8159841 | D361: 5.4506132 | E361: 4.6552618 | F361: 5.4582823 | G361: 4.1127072 | H361: 1.9 | I361: 8
A362: 44999 | B362: 2.6708509 | C362: 2.8115383 | D362: 5.4531144 | E362: 4.6470428 | F362: 5.4660798 | G362: 4.1073771 | H362: 1.9 | I362: 8
A363: 45000 | B363: 2.6455531 | C363: 2.7881824 | D363: 5.40793 | E363: 4.572171 | F363: 5.3991746 | G363: 4.0330245 | H363: 1.9 | I363: 8
A364: 45001 | B364: 2.6550202 | C364: 2.8099232 | D364: 5.4747359 | E364: 4.5926202 | F364: 5.4655905 | G364: 4.1139329 | H364: 1.9 | I364: 8
A365: 45002 | B365: 2.6363891 | C365: 2.7865766 | D365: 5.420292 | E365: 4.5496614 | F365: 5.3891409 | G365: 4.0570632 | H365: 1.9 | I365: 8
A366: 45005 | B366: 2.6404003 | C366: 2.7778625 | D366: 5.4360887 | E366: 4.5480765 | F366: 5.3888863 | G366: 4.0395905 | H366: 1.9 | I366: 8
A367: 45006 | B367: 2.654918 | C367: 2.7827532 | D367: 5.4572062 | E367: 4.5684378 | F367: 5.4038624 | G367: 4.1130431 | H367: 1.9 | I367: 8
... A494: 45189 | B494: 2.231379 | C494: 2.3440289 | D494: 5.2360055 | E494: 4.439343 | F494: 5.299946 | G494: 3.8005016 | H494: 1.9 | I494: 8
...

Sheet cnvxval
A1: DATES | B1: ZO283134 Corp | C1: ZO290323 Corp | D1: ZO305198 Corp | E1: ZO283163 Corp | F1: ZO283017 Corp | G1: ZO300955 Corp | H1: GT2 Govt | I1: GT10 Govt
A2: 44469 | B2: 0.22047454 | C2: 0.24523302 | D2: 0.9196152 | E2: 0.58772583 | F2: 0.72474384 | G2: 0.64966755 | H2: 0.045 | I2: 0.75
A3: 44470 | B3: 0.22039061 | C3: 0.24581382 | D3: 0.92319396 | E3: 0.58889506 | F3: 0.72798562 | G3: 0.6516508 | H3: 0.045 | I3: 0.7727
A4: 44473 | B4: 0.21995364 | C4: 0.24472182 | D4: 0.91861128 | E4: 0.58634625 | F4: 0.72321662 | G4: 0.65279964 | H4: 0.045 | I4: 0.7727
A5: 44474 | B5: 0.22053856 | C5: 0.24587429 | D5: 0.92410657 | E5: 0.58895554 | F5: 0.72913076 | G5: 0.65794419 | H5: 0.045 | I5: 0.7727
A6: 44475 | B6: 0.22029754 | C6: 0.24580589 | D6: 0.92461207 | E6: 0.58934056 | F6: 0.72838735 | G6: 0.66238132 | H6: 0.045 | I6: 0.7727
A7: 44476 | B7: 0.21977732 | C7: 0.24473457 | D7: 0.9231202 | E7: 0.58805139 | F7: 0.7267037 | G7: 0.65749914 | H7: 0.045 | I7: 0.7727
A8: 44477 | B8: 0.21861942 | C8: 0.24300479 | D8: 0.91579669 | E8: 0.58527936 | F8: 0.72197923 | G8: 0.65199429 | H8: 0.045 | I8: 0.7727
A9: 44481 | B9: 0.21718493 | C9: 0.24173486 | D9: 0.91163995 | E9: 0.58173102 | F9: 0.715531 | G9: 0.64451439 | H9: 0.045 | I9: 0.7727
A10: 44482 | B10: 0.21686623 | C10: 0.2412909 | D10: 0.90896195 | E10: 0.5802514 | F10: 0.71211546 | G10: 0.64188553 | H10: 0.045 | I10: 0.7727
A11: 44483 | B11: 0.21614882 | C11: 0.24055818 | D11: 0.90894864 | E11: 0.57964588 | F11: 0.71237756 | G11: 0.64201191 | H11: 0.045 | I11: 0.7727
A12: 44484 | B12: 0.21580185 | C12: 0.23985841 | D12: 0.90492936 | E12: 0.57785841 | F12: 0.70873335 | G12: 0.63791335 | H12: 0.045 | I12: 0.7727
A13: 44487 | B13: 0.21444413 | C13: 0.23770033 | D13: 0.89769829 | E13: 0.57450096 | F13: 0.70253021 | G13: 0.63022902 | H13: 0.045 | I13: 0.7727
... A1239: 46246 | B1239: 0.037392633 | C1239: 0.060175962 | D1239: 0.35031155 | E1239: 0.31590032 | F1239: 0.4960211 | G1239: 0.6434465 | H1239: 0.044527287 | I1239: 0.73478405

Sheet durvalnorm
A1: DATES | B1: GD29 | C1: GD30 | D1: GD35 | E1: GD38 | F1: GD41 | G1: GD46 | H1: GT2 | I1: GT10
A2: 44469 | B2: =+VLOOKUP(A2,durval!$A:$G,2,FALSE) -> 4.44957 | C2: =+VLOOKUP(A2,durval!$A:$G,3,FALSE) -> 4.690851 | D2: =+VLOOKUP(A2,durval!$A:$G,4,FALSE) -> 7.530655 | E2: =+VLOOKUP(A2,durval!$A:$G,5,FALSE) -> 6.36213 | F2: =+VLOOKUP(A2,durval!$A:$G,6,FALSE) -> 7.241406 | G2: =+VLOOKUP(A2,durval!$A:$G,7,FALSE) -> 6.608138 | H2: 1.9 | I2: 8
A3: 44470 | B3: =+VLOOKUP(A3,durval!$A:$G,2,FALSE) -> 4.448472 | C3: =+VLOOKUP(A3,durval!$A:$G,3,FALSE) -> 4.693331 | D3: =+VLOOKUP(A3,durval!$A:$G,4,FALSE) -> 7.545815 | E3: =+VLOOKUP(A3,durval!$A:$G,5,FALSE) -> 6.372225 | F3: =+VLOOKUP(A3,durval!$A:$G,6,FALSE) -> 7.259624 | G3: =+VLOOKUP(A3,durval!$A:$G,7,FALSE) -> 6.61954 | H3: 1.9 | I3: 8
A4: 44473 | B4: =+VLOOKUP(A4,durval!$A:$G,2,FALSE) -> 4.442652 | C4: =+VLOOKUP(A4,durval!$A:$G,3,FALSE) -> 4.68463 | D4: =+VLOOKUP(A4,durval!$A:$G,4,FALSE) -> 7.524181 | E4: =+VLOOKUP(A4,durval!$A:$G,5,FALSE) -> 6.350395 | F4: =+VLOOKUP(A4,durval!$A:$G,6,FALSE) -> 7.231305 | G4: =+VLOOKUP(A4,durval!$A:$G,7,FALSE) -> 6.627315 | H4: 1.9 | I4: 8
A5: 44474 | B5: =+VLOOKUP(A5,durval!$A:$G,2,FALSE) -> 4.450792 | C5: =+VLOOKUP(A5,durval!$A:$G,3,FALSE) -> 4.695053 | D5: =+VLOOKUP(A5,durval!$A:$G,4,FALSE) -> 7.551736 | E5: =+VLOOKUP(A5,durval!$A:$G,5,FALSE) -> 6.375261 | F5: =+VLOOKUP(A5,durval!$A:$G,6,FALSE) -> 7.269135 | G5: =+VLOOKUP(A5,durval!$A:$G,7,FALSE) -> 6.657704 | H5: 1.9 | I5: 8
A6: 44475 | B6: =+VLOOKUP(A6,durval!$A:$G,2,FALSE) -> 4.448024 | C6: =+VLOOKUP(A6,durval!$A:$G,3,FALSE) -> 4.696037 | D6: =+VLOOKUP(A6,durval!$A:$G,4,FALSE) -> 7.551599 | E6: =+VLOOKUP(A6,durval!$A:$G,5,FALSE) -> 6.378621 | F6: =+VLOOKUP(A6,durval!$A:$G,6,FALSE) -> 7.262405 | G6: =+VLOOKUP(A6,durval!$A:$G,7,FALSE) -> 6.685522 | H6: 1.9 | I6: 8
A7: 44476 | B7: =+IFERROR(VLOOKUP(A7,durval!$A:$G,2,FALSE),MEDIAN(B2:B6)) -> 4.441926 | C7: =+IFERROR(VLOOKUP(A7,durval!$A:$G,3,FALSE),MEDIAN(C2:C6)) -> 4.685357 | D7: =+IFERROR(VLOOKUP(A7,durval!$A:$G,4,FALSE),MEDIAN(D2:D6)) -> 7.545172 | E7: =+IFERROR(VLOOKUP(A7,durval!$A:$G,5,FALSE),MEDIAN(E2:E6)) -> 6.370912 | F7: =+IFERROR(VLOOKUP(A7,durval!$A:$G,6,FALSE),MEDIAN(F2:F6)) -> 7.252866 | G7: =+IFERROR(VLOOKUP(A7,durval!$A:$G,7,FALSE),MEDIAN(G2:G6)) -> 6.655221 | H7: 1.9 | I7: 8
A8: 44477 | B8: =+IFERROR(VLOOKUP(A8,durval!$A:$G,2,FALSE),MEDIAN(B3:B7)) -> 4.432304 | C8: =+IFERROR(VLOOKUP(A8,durval!$A:$G,3,FALSE),MEDIAN(C3:C7)) -> 4.669314 | D8: =+IFERROR(VLOOKUP(A8,durval!$A:$G,4,FALSE),MEDIAN(D3:D7)) -> 7.51128 | E8: =+IFERROR(VLOOKUP(A8,durval!$A:$G,5,FALSE),MEDIAN(E3:E7)) -> 6.347312 | F8: =+IFERROR(VLOOKUP(A8,durval!$A:$G,6,FALSE),MEDIAN(F3:F7)) -> 7.225239 | G8: =+IFERROR(VLOOKUP(A8,durval!$A:$G,7,FALSE),MEDIAN(G3:G7)) -> 6.622144 | H8: 1.9 | I8: 8
A9: 44481 | B9: =+IFERROR(VLOOKUP(A9,durval!$A:$G,2,FALSE),MEDIAN(B4:B8)) -> 4.416199 | C9: =+IFERROR(VLOOKUP(A9,durval!$A:$G,3,FALSE),MEDIAN(C4:C8)) -> 4.655774 | D9: =+IFERROR(VLOOKUP(A9,durval!$A:$G,4,FALSE),MEDIAN(D4:D8)) -> 7.484391 | E9: =+IFERROR(VLOOKUP(A9,durval!$A:$G,5,FALSE),MEDIAN(E4:E8)) -> 6.311435 | F9: =+IFERROR(VLOOKUP(A9,durval!$A:$G,6,FALSE),MEDIAN(F4:F8)) -> 7.181911 | G9: =+IFERROR(VLOOKUP(A9,durval!$A:$G,7,FALSE),MEDIAN(G4:G8)) -> 6.57628 | H9: 1.9 | I9: 8
A10: 44482 | B10: =+IFERROR(VLOOKUP(A10,durval!$A:$G,2,FALSE),MEDIAN(B5:B9)) -> 4.411212 | C10: =+IFERROR(VLOOKUP(A10,durval!$A:$G,3,FALSE),MEDIAN(C5:C9)) -> 4.648395 | D10: =+IFERROR(VLOOKUP(A10,durval!$A:$G,4,FALSE),MEDIAN(D5:D9)) -> 7.466938 | E10: =+IFERROR(VLOOKUP(A10,durval!$A:$G,5,FALSE),MEDIAN(E5:E9)) -> 6.294741 | F10: =+IFERROR(VLOOKUP(A10,durval!$A:$G,6,FALSE),MEDIAN(F5:F9)) -> 7.158123 | G10: =+IFERROR(VLOOKUP(A10,durval!$A:$G,7,FALSE),MEDIAN(G5:G9)) -> 6.560765 | H10: 1.9 | I10: 8
A11: 44483 | B11: =+IFERROR(VLOOKUP(A11,durval!$A:$G,2,FALSE),MEDIAN(B6:B10)) -> 4.402527 | C11: =+IFERROR(VLOOKUP(A11,durval!$A:$G,3,FALSE),MEDIAN(C6:C10)) -> 4.640254 | D11: =+IFERROR(VLOOKUP(A11,durval!$A:$G,4,FALSE),MEDIAN(D6:D10)) -> 7.464085 | E11: =+IFERROR(VLOOKUP(A11,durval!$A:$G,5,FALSE),MEDIAN(E6:E10)) -> 6.292271 | F11: =+IFERROR(VLOOKUP(A11,durval!$A:$G,6,FALSE),MEDIAN(F6:F10)) -> 7.158305 | G11: =+IFERROR(VLOOKUP(A11,durval!$A:$G,7,FALSE),MEDIAN(G6:G10)) -> 6.559752 | H11: 1.9 | I11: 8
A12: 44484 | B12: =+IFERROR(VLOOKUP(A12,durval!$A:$G,2,FALSE),MEDIAN(B7:B11)) -> 4.398756 | C12: =+IFERROR(VLOOKUP(A12,durval!$A:$G,3,FALSE),MEDIAN(C7:C11)) -> 4.634544 | D12: =+IFERROR(VLOOKUP(A12,durval!$A:$G,4,FALSE),MEDIAN(D7:D11)) -> 7.443593 | E12: =+IFERROR(VLOOKUP(A12,durval!$A:$G,5,FALSE),MEDIAN(E7:E11)) -> 6.274948 | F12: =+IFERROR(VLOOKUP(A12,durval!$A:$G,6,FALSE),MEDIAN(F7:F11)) -> 7.134649 | G12: =+IFERROR(VLOOKUP(A12,durval!$A:$G,7,FALSE),MEDIAN(G7:G11)) -> 6.535242 | H12: 1.9 | I12: 8
A13: 44487 | B13: =+IFERROR(VLOOKUP(A13,durval!$A:$G,2,FALSE),MEDIAN(B8:B12)) -> 4.384794 | C13: =+IFERROR(VLOOKUP(A13,durval!$A:$G,3,FALSE),MEDIAN(C8:C12)) -> 4.614144 | D13: =+IFERROR(VLOOKUP(A13,durval!$A:$G,4,FALSE),MEDIAN(D8:D12)) -> 7.40606 | E13: =+IFERROR(VLOOKUP(A13,durval!$A:$G,5,FALSE),MEDIAN(E8:E12)) -> 6.244613 | F13: =+IFERROR(VLOOKUP(A13,durval!$A:$G,6,FALSE),MEDIAN(F8:F12)) -> 7.095335 | G13: =+IFERROR(VLOOKUP(A13,durval!$A:$G,7,FALSE),MEDIAN(G8:G12)) -> 6.488893 | H13: 1.9 | I13: 8
A14: 44488 | B14: =+IFERROR(VLOOKUP(A14,durval!$A:$G,2,FALSE),MEDIAN(B9:B13)) -> 4.382805 | C14: =+IFERROR(VLOOKUP(A14,durval!$A:$G,3,FALSE),MEDIAN(C9:C13)) -> 4.619152 | D14: =+IFERROR(VLOOKUP(A14,durval!$A:$G,4,FALSE),MEDIAN(D9:D13)) -> 7.426562 | E14: =+IFERROR(VLOOKUP(A14,durval!$A:$G,5,FALSE),MEDIAN(E9:E13)) -> 6.248581 | F14: =+IFERROR(VLOOKUP(A14,durval!$A:$G,6,FALSE),MEDIAN(F9:F13)) -> 7.107673 | G14: =+IFERROR(VLOOKUP(A14,durval!$A:$G,7,FALSE),MEDIAN(G9:G13)) -> 6.504566 | H14: 1.9 | I14: 8
A15: 44489 | B15: =+IFERROR(VLOOKUP(A15,durval!$A:$G,2,FALSE),MEDIAN(B10:B14)) -> 4.38111 | C15: =+IFERROR(VLOOKUP(A15,durval!$A:$G,3,FALSE),MEDIAN(C10:C14)) -> 4.613887 | D15: =+IFERROR(VLOOKUP(A15,durval!$A:$G,4,FALSE),MEDIAN(D10:D14)) -> 7.424715 | E15: =+IFERROR(VLOOKUP(A15,durval!$A:$G,5,FALSE),MEDIAN(E10:E14)) -> 6.245906 | F15: =+IFERROR(VLOOKUP(A15,durval!$A:$G,6,FALSE),MEDIAN(F10:F14)) -> 7.106244 | G15: =+IFERROR(VLOOKUP(A15,durval!$A:$G,7,FALSE),MEDIAN(G10:G14)) -> 6.509805 | H15: 1.9 | I15: 8
A16: 44490 | B16: =+IFERROR(VLOOKUP(A16,durval!$A:$G,2,FALSE),MEDIAN(B11:B15)) -> 4.363801 | C16: =+IFERROR(VLOOKUP(A16,durval!$A:$G,3,FALSE),MEDIAN(C11:C15)) -> 4.594297 | D16: =+IFERROR(VLOOKUP(A16,durval!$A:$G,4,FALSE),MEDIAN(D11:D15)) -> 7.387165 | E16: =+IFERROR(VLOOKUP(A16,durval!$A:$G,5,FALSE),MEDIAN(E11:E15)) -> 6.217848 | F16: =+IFERROR(VLOOKUP(A16,durval!$A:$G,6,FALSE),MEDIAN(F11:F15)) -> 7.059352 | G16: =+IFERROR(VLOOKUP(A16,durval!$A:$G,7,FALSE),MEDIAN(G11:G15)) -> 6.471293 | H16: 1.9 | I16: 8
A17: 44491 | B17: =+IFERROR(VLOOKUP(A17,durval!$A:$G,2,FALSE),MEDIAN(B12:B16)) -> 4.349955 | C17: =+IFERROR(VLOOKUP(A17,durval!$A:$G,3,FALSE),MEDIAN(C12:C16)) -> 4.58091 | D17: =+IFERROR(VLOOKUP(A17,durval!$A:$G,4,FALSE),MEDIAN(D12:D16)) -> 7.353212 | E17: =+IFERROR(VLOOKUP(A17,durval!$A:$G,5,FALSE),MEDIAN(E12:E16)) -> 6.191263 | F17: =+IFERROR(VLOOKUP(A17,durval!$A:$G,6,FALSE),MEDIAN(F12:F16)) -> 7.034962 | G17: =+IFERROR(VLOOKUP(A17,durval!$A:$G,7,FALSE),MEDIAN(G12:G16)) -> 6.441064 | H17: 1.9 | I17: 8
A18: 44494 | B18: =+IFERROR(VLOOKUP(A18,durval!$A:$G,2,FALSE),MEDIAN(B13:B17)) -> 4.352994 | C18: =+IFERROR(VLOOKUP(A18,durval!$A:$G,3,FALSE),MEDIAN(C13:C17)) -> 4.586383 | D18: =+IFERROR(VLOOKUP(A18,durval!$A:$G,4,FALSE),MEDIAN(D13:D17)) -> 7.375831 | E18: =+IFERROR(VLOOKUP(A18,durval!$A:$G,5,FALSE),MEDIAN(E13:E17)) -> 6.201963 | F18: =+IFERROR(VLOOKUP(A18,durval!$A:$G,6,FALSE),MEDIAN(F13:F17)) -> 7.05129 | G18: =+IFERROR(VLOOKUP(A18,durval!$A:$G,7,FALSE),MEDIAN(G13:G17)) -> 6.446046 | H18: 1.9 | I18: 8
... A1285: 46246 | B1285: =+IFERROR(VLOOKUP(A1285,durval!$A:$G,2,FALSE),MEDIAN(B1280:B1284)) -> 1.5332135 | C1285: =+IFERROR(VLOOKUP(A1285,durval!$A:$G,3,FALSE),MEDIAN(C1280:C1284)) -> 1.9703346 | D1285: =+IFERROR(VLOOKUP(A1285,durval!$A:$G,4,FALSE),MEDIAN(D1280:D1284)) -> 5.2806736 | E1285: =+IFERROR(VLOOKUP(A1285,durval!$A:$G,5,FALSE),MEDIAN(E1280:E1284)) -> 4.5390134 | F1285: =+IFERROR(VLOOKUP(A1285,durval!$A:$G,6,FALSE),MEDIAN(F1280:F1284)) -> 5.7426699 | G1285: =+IFERROR(VLOOKUP(A1285,durval!$A:$G,7,FALSE),MEDIAN(G1280:G1284)) -> 6.1473821 | H1285: 1.9 | I1285: 8

Sheet cnvxvalnor
A1: DATES | B1: GD29 | C1: GD30 | D1: GD35 | E1: GD38 | F1: GD41 | G1: GD46 | H1: GT2 | I1: GT10
A2: 44469 | B2: =+VLOOKUP(A2,cnvxval!$A:$G,2,FALSE) -> 0.22047454 | C2: =+VLOOKUP(A2,cnvxval!$A:$G,3,FALSE) -> 0.24523302 | D2: =+VLOOKUP(A2,cnvxval!$A:$G,4,FALSE) -> 0.9196152 | E2: =+VLOOKUP(A2,cnvxval!$A:$G,5,FALSE) -> 0.58772583 | F2: =+VLOOKUP(A2,cnvxval!$A:$G,6,FALSE) -> 0.72474384 | G2: =+VLOOKUP(A2,cnvxval!$A:$G,7,FALSE) -> 0.64966755 | H2: 0.045 | I2: 0.75
A3: 44470 | B3: =+VLOOKUP(A3,cnvxval!$A:$G,2,FALSE) -> 0.22039061 | C3: =+VLOOKUP(A3,cnvxval!$A:$G,3,FALSE) -> 0.24581382 | D3: =+VLOOKUP(A3,cnvxval!$A:$G,4,FALSE) -> 0.92319396 | E3: =+VLOOKUP(A3,cnvxval!$A:$G,5,FALSE) -> 0.58889506 | F3: =+VLOOKUP(A3,cnvxval!$A:$G,6,FALSE) -> 0.72798562 | G3: =+VLOOKUP(A3,cnvxval!$A:$G,7,FALSE) -> 0.6516508 | H3: 0.045 | I3: 0.7727
A4: 44473 | B4: =+VLOOKUP(A4,cnvxval!$A:$G,2,FALSE) -> 0.21995364 | C4: =+VLOOKUP(A4,cnvxval!$A:$G,3,FALSE) -> 0.24472182 | D4: =+VLOOKUP(A4,cnvxval!$A:$G,4,FALSE) -> 0.91861128 | E4: =+VLOOKUP(A4,cnvxval!$A:$G,5,FALSE) -> 0.58634625 | F4: =+VLOOKUP(A4,cnvxval!$A:$G,6,FALSE) -> 0.72321662 | G4: =+VLOOKUP(A4,cnvxval!$A:$G,7,FALSE) -> 0.65279964 | H4: 0.045 | I4: 0.7727
A5: 44474 | B5: =+VLOOKUP(A5,cnvxval!$A:$G,2,FALSE) -> 0.22053856 | C5: =+VLOOKUP(A5,cnvxval!$A:$G,3,FALSE) -> 0.24587429 | D5: =+VLOOKUP(A5,cnvxval!$A:$G,4,FALSE) -> 0.92410657 | E5: =+VLOOKUP(A5,cnvxval!$A:$G,5,FALSE) -> 0.58895554 | F5: =+VLOOKUP(A5,cnvxval!$A:$G,6,FALSE) -> 0.72913076 | G5: =+VLOOKUP(A5,cnvxval!$A:$G,7,FALSE) -> 0.65794419 | H5: 0.045 | I5: 0.7727
A6: 44475 | B6: =+VLOOKUP(A6,cnvxval!$A:$G,2,FALSE) -> 0.22029754 | C6: =+VLOOKUP(A6,cnvxval!$A:$G,3,FALSE) -> 0.24580589 | D6: =+VLOOKUP(A6,cnvxval!$A:$G,4,FALSE) -> 0.92461207 | E6: =+VLOOKUP(A6,cnvxval!$A:$G,5,FALSE) -> 0.58934056 | F6: =+VLOOKUP(A6,cnvxval!$A:$G,6,FALSE) -> 0.72838735 | G6: =+VLOOKUP(A6,cnvxval!$A:$G,7,FALSE) -> 0.66238132 | H6: 0.045 | I6: 0.7727
A7: 44476 | B7: =+IFERROR(VLOOKUP(A7,cnvxval!$A:$G,2,FALSE),MEDIAN(B2:B6)) -> 0.21977732 | C7: =+IFERROR(VLOOKUP(A7,cnvxval!$A:$G,3,FALSE),MEDIAN(C2:C6)) -> 0.24473457 | D7: =+IFERROR(VLOOKUP(A7,cnvxval!$A:$G,4,FALSE),MEDIAN(D2:D6)) -> 0.9231202 | E7: =+IFERROR(VLOOKUP(A7,cnvxval!$A:$G,5,FALSE),MEDIAN(E2:E6)) -> 0.58805139 | F7: =+IFERROR(VLOOKUP(A7,cnvxval!$A:$G,6,FALSE),MEDIAN(F2:F6)) -> 0.7267037 | G7: =+IFERROR(VLOOKUP(A7,cnvxval!$A:$G,7,FALSE),MEDIAN(G2:G6)) -> 0.65749914 | H7: 0.045 | I7: 0.7727
A8: 44477 | B8: =+IFERROR(VLOOKUP(A8,cnvxval!$A:$G,2,FALSE),MEDIAN(B3:B7)) -> 0.21861942 | C8: =+IFERROR(VLOOKUP(A8,cnvxval!$A:$G,3,FALSE),MEDIAN(C3:C7)) -> 0.24300479 | D8: =+IFERROR(VLOOKUP(A8,cnvxval!$A:$G,4,FALSE),MEDIAN(D3:D7)) -> 0.91579669 | E8: =+IFERROR(VLOOKUP(A8,cnvxval!$A:$G,5,FALSE),MEDIAN(E3:E7)) -> 0.58527936 | F8: =+IFERROR(VLOOKUP(A8,cnvxval!$A:$G,6,FALSE),MEDIAN(F3:F7)) -> 0.72197923 | G8: =+IFERROR(VLOOKUP(A8,cnvxval!$A:$G,7,FALSE),MEDIAN(G3:G7)) -> 0.65199429 | H8: 0.045 | I8: 0.7727
A9: 44481 | B9: =+IFERROR(VLOOKUP(A9,cnvxval!$A:$G,2,FALSE),MEDIAN(B4:B8)) -> 0.21718493 | C9: =+IFERROR(VLOOKUP(A9,cnvxval!$A:$G,3,FALSE),MEDIAN(C4:C8)) -> 0.24173486 | D9: =+IFERROR(VLOOKUP(A9,cnvxval!$A:$G,4,FALSE),MEDIAN(D4:D8)) -> 0.91163995 | E9: =+IFERROR(VLOOKUP(A9,cnvxval!$A:$G,5,FALSE),MEDIAN(E4:E8)) -> 0.58173102 | F9: =+IFERROR(VLOOKUP(A9,cnvxval!$A:$G,6,FALSE),MEDIAN(F4:F8)) -> 0.715531 | G9: =+IFERROR(VLOOKUP(A9,cnvxval!$A:$G,7,FALSE),MEDIAN(G4:G8)) -> 0.64451439 | H9: 0.045 | I9: 0.7727
A10: 44482 | B10: =+IFERROR(VLOOKUP(A10,cnvxval!$A:$G,2,FALSE),MEDIAN(B5:B9)) -> 0.21686623 | C10: =+IFERROR(VLOOKUP(A10,cnvxval!$A:$G,3,FALSE),MEDIAN(C5:C9)) -> 0.2412909 | D10: =+IFERROR(VLOOKUP(A10,cnvxval!$A:$G,4,FALSE),MEDIAN(D5:D9)) -> 0.90896195 | E10: =+IFERROR(VLOOKUP(A10,cnvxval!$A:$G,5,FALSE),MEDIAN(E5:E9)) -> 0.5802514 | F10: =+IFERROR(VLOOKUP(A10,cnvxval!$A:$G,6,FALSE),MEDIAN(F5:F9)) -> 0.71211546 | G10: =+IFERROR(VLOOKUP(A10,cnvxval!$A:$G,7,FALSE),MEDIAN(G5:G9)) -> 0.64188553 | H10: 0.045 | I10: 0.7727
A11: 44483 | B11: =+IFERROR(VLOOKUP(A11,cnvxval!$A:$G,2,FALSE),MEDIAN(B6:B10)) -> 0.21614882 | C11: =+IFERROR(VLOOKUP(A11,cnvxval!$A:$G,3,FALSE),MEDIAN(C6:C10)) -> 0.24055818 | D11: =+IFERROR(VLOOKUP(A11,cnvxval!$A:$G,4,FALSE),MEDIAN(D6:D10)) -> 0.90894864 | E11: =+IFERROR(VLOOKUP(A11,cnvxval!$A:$G,5,FALSE),MEDIAN(E6:E10)) -> 0.57964588 | F11: =+IFERROR(VLOOKUP(A11,cnvxval!$A:$G,6,FALSE),MEDIAN(F6:F10)) -> 0.71237756 | G11: =+IFERROR(VLOOKUP(A11,cnvxval!$A:$G,7,FALSE),MEDIAN(G6:G10)) -> 0.64201191 | H11: 0.045 | I11: 0.7727
A12: 44484 | B12: =+IFERROR(VLOOKUP(A12,cnvxval!$A:$G,2,FALSE),MEDIAN(B7:B11)) -> 0.21580185 | C12: =+IFERROR(VLOOKUP(A12,cnvxval!$A:$G,3,FALSE),MEDIAN(C7:C11)) -> 0.23985841 | D12: =+IFERROR(VLOOKUP(A12,cnvxval!$A:$G,4,FALSE),MEDIAN(D7:D11)) -> 0.90492936 | E12: =+IFERROR(VLOOKUP(A12,cnvxval!$A:$G,5,FALSE),MEDIAN(E7:E11)) -> 0.57785841 | F12: =+IFERROR(VLOOKUP(A12,cnvxval!$A:$G,6,FALSE),MEDIAN(F7:F11)) -> 0.70873335 | G12: =+IFERROR(VLOOKUP(A12,cnvxval!$A:$G,7,FALSE),MEDIAN(G7:G11)) -> 0.63791335 | H12: 0.045 | I12: 0.7727
A13: 44487 | B13: =+IFERROR(VLOOKUP(A13,cnvxval!$A:$G,2,FALSE),MEDIAN(B8:B12)) -> 0.21444413 | C13: =+IFERROR(VLOOKUP(A13,cnvxval!$A:$G,3,FALSE),MEDIAN(C8:C12)) -> 0.23770033 | D13: =+IFERROR(VLOOKUP(A13,cnvxval!$A:$G,4,FALSE),MEDIAN(D8:D12)) -> 0.89769829 | E13: =+IFERROR(VLOOKUP(A13,cnvxval!$A:$G,5,FALSE),MEDIAN(E8:E12)) -> 0.57450096 | F13: =+IFERROR(VLOOKUP(A13,cnvxval!$A:$G,6,FALSE),MEDIAN(F8:F12)) -> 0.70253021 | G13: =+IFERROR(VLOOKUP(A13,cnvxval!$A:$G,7,FALSE),MEDIAN(G8:G12)) -> 0.63022902 | H13: 0.045 | I13: 0.7727
A14: 44488 | B14: =+IFERROR(VLOOKUP(A14,cnvxval!$A:$G,2,FALSE),MEDIAN(B9:B13)) -> 0.21419996 | C14: =+IFERROR(VLOOKUP(A14,cnvxval!$A:$G,3,FALSE),MEDIAN(C9:C13)) -> 0.23830446 | D14: =+IFERROR(VLOOKUP(A14,cnvxval!$A:$G,4,FALSE),MEDIAN(D9:D13)) -> 0.90083606 | E14: =+IFERROR(VLOOKUP(A14,cnvxval!$A:$G,5,FALSE),MEDIAN(E9:E13)) -> 0.57458655 | F14: =+IFERROR(VLOOKUP(A14,cnvxval!$A:$G,6,FALSE),MEDIAN(F9:F13)) -> 0.70387513 | G14: =+IFERROR(VLOOKUP(A14,cnvxval!$A:$G,7,FALSE),MEDIAN(G9:G13)) -> 0.63275064 | H14: 0.045 | I14: 0.7727
A15: 44489 | B15: =+IFERROR(VLOOKUP(A15,cnvxval!$A:$G,2,FALSE),MEDIAN(B10:B14)) -> 0.21400843 | C15: =+IFERROR(VLOOKUP(A15,cnvxval!$A:$G,3,FALSE),MEDIAN(C10:C14)) -> 0.23766217 | D15: =+IFERROR(VLOOKUP(A15,cnvxval!$A:$G,4,FALSE),MEDIAN(D10:D14)) -> 0.90010482 | E15: =+IFERROR(VLOOKUP(A15,cnvxval!$A:$G,5,FALSE),MEDIAN(E10:E14)) -> 0.5741361 | F15: =+IFERROR(VLOOKUP(A15,cnvxval!$A:$G,6,FALSE),MEDIAN(F10:F14)) -> 0.70348942 | G15: =+IFERROR(VLOOKUP(A15,cnvxval!$A:$G,7,FALSE),MEDIAN(G10:G14)) -> 0.63373488 | H15: 0.045 | I15: 0.7727
A16: 44490 | B16: =+IFERROR(VLOOKUP(A16,cnvxval!$A:$G,2,FALSE),MEDIAN(B11:B15)) -> 0.21227719 | C16: =+IFERROR(VLOOKUP(A16,cnvxval!$A:$G,3,FALSE),MEDIAN(C11:C15)) -> 0.23581433 | D16: =+IFERROR(VLOOKUP(A16,cnvxval!$A:$G,4,FALSE),MEDIAN(D11:D15)) -> 0.89316775 | E16: =+IFERROR(VLOOKUP(A16,cnvxval!$A:$G,5,FALSE),MEDIAN(E11:E15)) -> 0.57112696 | F16: =+IFERROR(VLOOKUP(A16,cnvxval!$A:$G,6,FALSE),MEDIAN(F11:F15)) -> 0.69628532 | G16: =+IFERROR(VLOOKUP(A16,cnvxval!$A:$G,7,FALSE),MEDIAN(G11:G15)) -> 0.62750217 | H16: 0.045 | I16: 0.7727
A17: 44491 | B17: =+IFERROR(VLOOKUP(A17,cnvxval!$A:$G,2,FALSE),MEDIAN(B12:B16)) -> 0.21123042 | C17: =+IFERROR(VLOOKUP(A17,cnvxval!$A:$G,3,FALSE),MEDIAN(C12:C16)) -> 0.23457301 | D17: =+IFERROR(VLOOKUP(A17,cnvxval!$A:$G,4,FALSE),MEDIAN(D12:D16)) -> 0.88685335 | E17: =+IFERROR(VLOOKUP(A17,cnvxval!$A:$G,5,FALSE),MEDIAN(E12:E16)) -> 0.56848138 | F17: =+IFERROR(VLOOKUP(A17,cnvxval!$A:$G,6,FALSE),MEDIAN(F12:F16)) -> 0.69229458 | G17: =+IFERROR(VLOOKUP(A17,cnvxval!$A:$G,7,FALSE),MEDIAN(G12:G16)) -> 0.62261137 | H17: 0.045 | I17: 0.7727
A18: 44494 | B18: =+IFERROR(VLOOKUP(A18,cnvxval!$A:$G,2,FALSE),MEDIAN(B13:B17)) -> 0.21155169 | C18: =+IFERROR(VLOOKUP(A18,cnvxval!$A:$G,3,FALSE),MEDIAN(C13:C17)) -> 0.23497665 | D18: =+IFERROR(VLOOKUP(A18,cnvxval!$A:$G,4,FALSE),MEDIAN(D13:D17)) -> 0.89125063 | E18: =+IFERROR(VLOOKUP(A18,cnvxval!$A:$G,5,FALSE),MEDIAN(E13:E17)) -> 0.56932009 | F18: =+IFERROR(VLOOKUP(A18,cnvxval!$A:$G,6,FALSE),MEDIAN(F13:F17)) -> 0.69528347 | G18: =+IFERROR(VLOOKUP(A18,cnvxval!$A:$G,7,FALSE),MEDIAN(G13:G17)) -> 0.62357483 | H18: 0.045 | I18: 0.7727
... A1275: 46246 | B1275: =+IFERROR(VLOOKUP(A1275,cnvxval!$A:$G,2,FALSE),MEDIAN(B1270:B1274)) -> 0.037392633 | C1275: =+IFERROR(VLOOKUP(A1275,cnvxval!$A:$G,3,FALSE),MEDIAN(C1270:C1274)) -> 0.060175962 | D1275: =+IFERROR(VLOOKUP(A1275,cnvxval!$A:$G,4,FALSE),MEDIAN(D1270:D1274)) -> 0.35031155 | E1275: =+IFERROR(VLOOKUP(A1275,cnvxval!$A:$G,5,FALSE),MEDIAN(E1270:E1274)) -> 0.31590032 | F1275: =+IFERROR(VLOOKUP(A1275,cnvxval!$A:$G,6,FALSE),MEDIAN(F1270:F1274)) -> 0.4960211 | G1275: =+IFERROR(VLOOKUP(A1275,cnvxval!$A:$G,7,FALSE),MEDIAN(G1270:G1274)) -> 0.6434465 | H1275: 0.046287062 | I1275: 0.76041341
