Workbook

Sheet MARKET WEIGHT
A1: Fecha: | B1: 45922
B3: Shares | C3: Pxs | D3: Weight
A4: ALUA AR Equity | B4: 1060.0284 | C4: 880 | D4: =+(B4*C4)/SUMPRODUCT($B$4:$B$23,$C$4:$C$23) -> 0.023446268
A5: BBAR AR Equity | B5: 283.50766 | C5: 7090 | D5: =+(B5*C5)/SUMPRODUCT($B$4:$B$23,$C$4:$C$23) -> 0.050522471
A6: BMA AR Equity | B6: 308.28093 | C6: 10350 | D6: =+(B6*C6)/SUMPRODUCT($B$4:$B$23,$C$4:$C$23) -> 0.080197451
A7: BYMA AR Equity | B7: 7377.0836 | C7: 309.75 | D7: =+(B7*C7)/SUMPRODUCT($B$4:$B$23,$C$4:$C$23) -> 0.057434067
A8: CEPU AR Equity | B8: 1358.651 | C8: 2284 | D8: =+(B8*C8)/SUMPRODUCT($B$4:$B$23,$C$4:$C$23) -> 0.077996941
A9: COME AR Equity | B9: 9815.0828 | C9: 50.799999 | D9: =+(B9*C9)/SUMPRODUCT($B$4:$B$23,$C$4:$C$23) -> 0.012532313
A10: CRES AR Equity | B10: 554.87843 | C10: 1808 | D10: =+(B10*C10)/SUMPRODUCT($B$4:$B$23,$C$4:$C$23) -> 0.02521563
A11: ECOG AR Equity | B11: 154.58927 | C11: 2915 | D11: =+(B11*C11)/SUMPRODUCT($B$4:$B$23,$C$4:$C$23) -> 0.011326389
A12: EDN AR Equity | B12: 235.80733 | C12: 2065 | D12: =+(B12*C12)/SUMPRODUCT($B$4:$B$23,$C$4:$C$23) -> 0.01223914
A13: GGAL AR Equity | B13: 882.41544 | C13: 6340 | D13: =+(B13*C13)/SUMPRODUCT($B$4:$B$23,$C$4:$C$23) -> 0.14061638
A14: LOMA AR Equity | B14: 392.70376 | C14: 3067.5 | D14: =+(B14*C14)/SUMPRODUCT($B$4:$B$23,$C$4:$C$23) -> 0.030277721
A15: METR AR Equity | B15: 164.24202 | C15: 1987 | D15: =+(B15*C15)/SUMPRODUCT($B$4:$B$23,$C$4:$C$23) -> 0.0082026787
... A23: YPFD AR Equity | B23: 101.87676 | C23: 67925 | D23: =+(B23*C23)/SUMPRODUCT($B$4:$B$23,$C$4:$C$23) -> 0.17393153
A25: CHECK | D25: =SUM(D4:D23) -> 1

Sheet MARKET PXS
A1: {=_xll.BQL(_xlfn._LONGTEXT("['GGAL AR Equity'; 'PAMP AR Equity'; 'YPFD AR Equity'; 'BMA AR Equity'; 'CEPU AR Equity'; 'BYMA AR Equity'; 'BBAR AR Equity'; 'TGSU2 AR Equity'; 'TXAR AR Equity'; 'LOMA AR Equity'; 'SUPV AR Equity'; 'ALUA AR Equity'; 'TECO2 AR Equity'; 'ECOG AR Equity'; '","CRES AR Equity'; 'COME AR Equity'; 'TRAN AR Equity'; 'VALO AR Equity'; 'EDN AR Equity'; 'TGNO4 AR Equity'; 'METR AR Equity']"), "dropna(px_last(ca_adj='FULL'; currency='ARS'; dates=range(-100M, 0D)))", "transpose", "false")} -> #NAME?

Sheet INPUT PX
A1: =+'MARKET PXS'!A2 -> 0 | B1: =_xlfn.TEXTBEFORE('MARKET PXS'!B1,"AR Equity",1,0,1) -> #VALUE! | C1: =_xlfn.TEXTBEFORE('MARKET PXS'!C1,"AR Equity",1,0,1) -> #VALUE! | D1: =_xlfn.TEXTBEFORE('MARKET PXS'!D1,"AR Equity",1,0,1) -> #VALUE! | E1: =_xlfn.TEXTBEFORE('MARKET PXS'!E1,"AR Equity",1,0,1) -> #VALUE! | F1: =_xlfn.TEXTBEFORE('MARKET PXS'!F1,"AR Equity",1,0,1) -> #VALUE! | G1: =_xlfn.TEXTBEFORE('MARKET PXS'!G1,"AR Equity",1,0,1) -> #VALUE! | H1: =_xlfn.TEXTBEFORE('MARKET PXS'!H1,"AR Equity",1,0,1) -> #VALUE! | I1: =_xlfn.TEXTBEFORE('MARKET PXS'!I1,"AR Equity",1,0,1) -> #VALUE! | ... V1: =_xlfn.TEXTBEFORE('MARKET PXS'!V1,"AR Equity",1,0,1) -> #VALUE!
A2: =+'MARKET PXS'!A3 -> 0 | B2: =+'MARKET PXS'!B3 -> 0 | C2: =+'MARKET PXS'!C3 -> 0 | D2: =+'MARKET PXS'!D3 -> 0 | E2: =+'MARKET PXS'!E3 -> 0 | F2: =+'MARKET PXS'!F3 -> 0 | G2: =+'MARKET PXS'!G3 -> 0 | H2: =+'MARKET PXS'!H3 -> 0 | ... V2: =+'MARKET PXS'!V3 -> 0
A3: =+'MARKET PXS'!A4 -> 0 | B3: =+'MARKET PXS'!B4 -> 0 | C3: =+'MARKET PXS'!C4 -> 0 | D3: =+'MARKET PXS'!D4 -> 0 | E3: =+'MARKET PXS'!E4 -> 0 | F3: =+'MARKET PXS'!F4 -> 0 | G3: =+'MARKET PXS'!G4 -> 0 | H3: =+'MARKET PXS'!H4 -> 0 | ... V3: =+'MARKET PXS'!V4 -> 0
A4: =+'MARKET PXS'!A5 -> 0 | B4: =+'MARKET PXS'!B5 -> 0 | C4: =+'MARKET PXS'!C5 -> 0 | D4: =+'MARKET PXS'!D5 -> 0 | E4: =+'MARKET PXS'!E5 -> 0 | F4: =+'MARKET PXS'!F5 -> 0 | G4: =+'MARKET PXS'!G5 -> 0 | H4: =+'MARKET PXS'!H5 -> 0 | ... V4: =+'MARKET PXS'!V5 -> 0
A5: =+'MARKET PXS'!A6 -> 0 | B5: =+'MARKET PXS'!B6 -> 0 | C5: =+'MARKET PXS'!C6 -> 0 | D5: =+'MARKET PXS'!D6 -> 0 | E5: =+'MARKET PXS'!E6 -> 0 | F5: =+'MARKET PXS'!F6 -> 0 | G5: =+'MARKET PXS'!G6 -> 0 | H5: =+'MARKET PXS'!H6 -> 0 | ... V5: =+'MARKET PXS'!V6 -> 0
A6: =+'MARKET PXS'!A7 -> 0 | B6: =+'MARKET PXS'!B7 -> 0 | C6: =+'MARKET PXS'!C7 -> 0 | D6: =+'MARKET PXS'!D7 -> 0 | E6: =+'MARKET PXS'!E7 -> 0 | F6: =+'MARKET PXS'!F7 -> 0 | G6: =+'MARKET PXS'!G7 -> 0 | H6: =+'MARKET PXS'!H7 -> 0 | ... V6: =+'MARKET PXS'!V7 -> 0
A7: =+'MARKET PXS'!A8 -> 0 | B7: =+'MARKET PXS'!B8 -> 0 | C7: =+'MARKET PXS'!C8 -> 0 | D7: =+'MARKET PXS'!D8 -> 0 | E7: =+'MARKET PXS'!E8 -> 0 | F7: =+'MARKET PXS'!F8 -> 0 | G7: =+'MARKET PXS'!G8 -> 0 | H7: =+'MARKET PXS'!H8 -> 0 | ... V7: =+'MARKET PXS'!V8 -> 0
A8: =+'MARKET PXS'!A9 -> 0 | B8: =+'MARKET PXS'!B9 -> 0 | C8: =+'MARKET PXS'!C9 -> 0 | D8: =+'MARKET PXS'!D9 -> 0 | E8: =+'MARKET PXS'!E9 -> 0 | F8: =+'MARKET PXS'!F9 -> 0 | G8: =+'MARKET PXS'!G9 -> 0 | H8: =+'MARKET PXS'!H9 -> 0 | ... V8: =+'MARKET PXS'!V9 -> 0
A9: =+'MARKET PXS'!A10 -> 0 | B9: =+'MARKET PXS'!B10 -> 0 | C9: =+'MARKET PXS'!C10 -> 0 | D9: =+'MARKET PXS'!D10 -> 0 | E9: =+'MARKET PXS'!E10 -> 0 | F9: =+'MARKET PXS'!F10 -> 0 | G9: =+'MARKET PXS'!G10 -> 0 | H9: =+'MARKET PXS'!H10 -> 0 | ... V9: =+'MARKET PXS'!V10 -> 0
A10: =+'MARKET PXS'!A11 -> 0 | B10: =+'MARKET PXS'!B11 -> 0 | C10: =+'MARKET PXS'!C11 -> 0 | D10: =+'MARKET PXS'!D11 -> 0 | E10: =+'MARKET PXS'!E11 -> 0 | F10: =+'MARKET PXS'!F11 -> 0 | G10: =+'MARKET PXS'!G11 -> 0 | H10: =+'MARKET PXS'!H11 -> 0 | ... V10: =+'MARKET PXS'!V11 -> 0
A11: =+'MARKET PXS'!A12 -> 0 | B11: =+'MARKET PXS'!B12 -> 0 | C11: =+'MARKET PXS'!C12 -> 0 | D11: =+'MARKET PXS'!D12 -> 0 | E11: =+'MARKET PXS'!E12 -> 0 | F11: =+'MARKET PXS'!F12 -> 0 | G11: =+'MARKET PXS'!G12 -> 0 | H11: =+'MARKET PXS'!H12 -> 0 | ... V11: =+'MARKET PXS'!V12 -> 0
A12: =+'MARKET PXS'!A13 -> 0 | B12: =+'MARKET PXS'!B13 -> 0 | C12: =+'MARKET PXS'!C13 -> 0 | D12: =+'MARKET PXS'!D13 -> 0 | E12: =+'MARKET PXS'!E13 -> 0 | F12: =+'MARKET PXS'!F13 -> 0 | G12: =+'MARKET PXS'!G13 -> 0 | H12: =+'MARKET PXS'!H13 -> 0 | ... V12: =+'MARKET PXS'!V13 -> 0
A13: =+'MARKET PXS'!A14 -> 0 | B13: =+'MARKET PXS'!B14 -> 0 | C13: =+'MARKET PXS'!C14 -> 0 | D13: =+'MARKET PXS'!D14 -> 0 | E13: =+'MARKET PXS'!E14 -> 0 | F13: =+'MARKET PXS'!F14 -> 0 | G13: =+'MARKET PXS'!G14 -> 0 | H13: =+'MARKET PXS'!H14 -> 0 | ... V13: =+'MARKET PXS'!V14 -> 0
... A2029: =+'MARKET PXS'!A2030 -> 0 | B2029: =+'MARKET PXS'!B2030 -> 0 | C2029: =+'MARKET PXS'!C2030 -> 0 | D2029: =+'MARKET PXS'!D2030 -> 0 | E2029: =+'MARKET PXS'!E2030 -> 0 | F2029: =+'MARKET PXS'!F2030 -> 0 | G2029: =+'MARKET PXS'!G2030 -> 0 | H2029: =+'MARKET PXS'!H2030 -> 0 | ... V2029: =+'MARKET PXS'!V2030 -> 0

Sheet INPUT W
A1: ticker | B1: weight
A2: =_xlfn.TEXTBEFORE('MARKET WEIGHT'!A4,"AR Equity",1,0,1) -> ALUA | B2: =+'MARKET WEIGHT'!D4 -> 0.023446268
A3: =_xlfn.TEXTBEFORE('MARKET WEIGHT'!A5,"AR Equity",1,0,1) -> BBAR | B3: =+'MARKET WEIGHT'!D5 -> 0.050522471
A4: =_xlfn.TEXTBEFORE('MARKET WEIGHT'!A6,"AR Equity",1,0,1) -> BMA | B4: =+'MARKET WEIGHT'!D6 -> 0.080197451
A5: =_xlfn.TEXTBEFORE('MARKET WEIGHT'!A7,"AR Equity",1,0,1) -> BYMA | B5: =+'MARKET WEIGHT'!D7 -> 0.057434067
A6: =_xlfn.TEXTBEFORE('MARKET WEIGHT'!A8,"AR Equity",1,0,1) -> CEPU | B6: =+'MARKET WEIGHT'!D8 -> 0.077996941
A7: =_xlfn.TEXTBEFORE('MARKET WEIGHT'!A9,"AR Equity",1,0,1) -> COME | B7: =+'MARKET WEIGHT'!D9 -> 0.012532313
A8: =_xlfn.TEXTBEFORE('MARKET WEIGHT'!A10,"AR Equity",1,0,1) -> CRES | B8: =+'MARKET WEIGHT'!D10 -> 0.02521563
A9: =_xlfn.TEXTBEFORE('MARKET WEIGHT'!A11,"AR Equity",1,0,1) -> ECOG | B9: =+'MARKET WEIGHT'!D11 -> 0.011326389
A10: =_xlfn.TEXTBEFORE('MARKET WEIGHT'!A12,"AR Equity",1,0,1) -> EDN | B10: =+'MARKET WEIGHT'!D12 -> 0.01223914
A11: =_xlfn.TEXTBEFORE('MARKET WEIGHT'!A13,"AR Equity",1,0,1) -> GGAL | B11: =+'MARKET WEIGHT'!D13 -> 0.14061638
A12: =_xlfn.TEXTBEFORE('MARKET WEIGHT'!A14,"AR Equity",1,0,1) -> LOMA | B12: =+'MARKET WEIGHT'!D14 -> 0.030277721
A13: =_xlfn.TEXTBEFORE('MARKET WEIGHT'!A15,"AR Equity",1,0,1) -> METR | B13: =+'MARKET WEIGHT'!D15 -> 0.0082026787
... A21: =_xlfn.TEXTBEFORE('MARKET WEIGHT'!A23,"AR Equity",1,0,1) -> YPFD | B21: =+'MARKET WEIGHT'!D23 -> 0.17393153

Sheet INPUT A VALOR PX
A1: DATES | B1: GGAL | C1: PAMP | D1: YPFD | E1: BMA | F1: CEPU | G1: BYMA | H1: BBAR | I1: TGSU2 | J1: TXAR | K1: LOMA | L1: SUPV | M1: ALUA | N1: TECO2 | O1: ECOG | P1: CRES | Q1: COME | R1: TRAN | S1: VALO | T1: EDN | U1: TGNO4 | V1: METR
A2: 43069 | B2: 72.424437 | C2: 44.3 | D2: 384.5043 | E2: 124.72483 | F2: 24.898929 | G2: 1.898806 | H2: 79.861949 | I2: 59.285879 | J2: 9.6978562 | K2: 65.840383 | L2: 81.047521 | M2: 10.143083 | N2: 95.338831 | O2: #N/A | P2: 22.717655 | Q2: 0.74750526 | R2: 30.440279 | S2: 4.3026172 | T2: 39 | U2: 45.0251 | V2: 36
A3: 43070 | B3: 72.898037 | C3: 44 | D3: 388.97129 | E3: 123.95427 | F3: 25.066881 | G3: 1.922152 | H3: 78.609471 | I3: 58.804532 | J3: 9.5888915 | K3: 64.150001 | L3: 80.869297 | M3: 10.104951 | N3: 98.462749 | O3: #N/A | P3: 23.275523 | Q3: 0.73700167 | R3: 31.118992 | S3: 4.2730459 | T3: 38 | U3: 44.426643 | V3: 37.9
A4: 43073 | B4: 73.808807 | C4: 43.2 | D4: 390.05122 | E4: 126.51111 | F4: 25.024893 | G4: 1.922152 | H4: 79.10387 | I4: 58.162736 | J4: 9.4072837 | K4: 63.558367 | L4: 81.582194 | M4: 9.87616 | N4: 99.174528 | O4: #N/A | P4: 22.717655 | Q4: 0.72474749 | R4: 30.949314 | S4: 4.3247956 | T4: 37.45 | U4: 43.687372 | V4: 37
A5: 43074 | B5: 74.136685 | C5: 42.75 | D5: 376.65026 | E5: 127.91212 | F5: 24.605012 | G5: 1.9999719 | H5: 80.323388 | I5: 59.005093 | J5: 9.3346406 | K5: 62.544138 | L5: 81.537638 | M5: 9.6855006 | N5: 100.16311 | O5: #N/A | P5: 22.066808 | Q5: 0.71949569 | R5: 29.863373 | S5: 4.3543669 | T5: 37.75 | U5: 42.983305 | V5: 36.55
A6: 43075 | B6: 74.82887 | C6: 43.7 | D6: 380.38093 | E6: 137.29888 | F6: 24.143143 | G6: 2.0388819 | H6: 81.905466 | I6: 58.563859 | J6: 9.0803897 | K6: 62.544138 | L6: 83.141657 | M6: 9.6855006 | N6: 101.38895 | O6: #N/A | P6: 22.035815 | Q6: 0.7142439 | R6: 29.388274 | S6: 4.54658 | T6: 38.35 | U6: 43.581762 | V6: 36.5
A7: 43076 | B7: 77.56118 | C7: 44.3 | D7: 377.63202 | E7: 139.4004 | F7: 24.143143 | G7: 2.101916 | H7: 83.124984 | I7: 60.168348 | J7: 9.4072837 | K7: 63.389329 | L7: 85.146681 | M7: 10.066819 | N7: 101.30986 | O7: #N/A | P7: 22.221771 | Q7: 0.75275705 | R7: 30.406344 | S7: 4.6722579 | T7: 40.5 | U7: 43.476152 | V7: 37.5
A8: 43080 | B8: 81.20426 | C8: 44.35 | D8: 375.03037 | E8: 144.96941 | F8: 25.150857 | G8: 2.1244838 | H8: 85.13554 | I8: 64.059234 | J8: 9.5888915 | K8: 64.23452 | L8: 87.953714 | M8: 9.9524238 | N8: 101.19124 | O8: #N/A | P8: 22.531699 | Q8: 0.74575466 | R8: 30.508151 | S8: 4.7387932 | T8: 42.2 | U8: 45.764371 | V8: 38.9
A9: 43081 | B9: 81.568568 | C9: 44.6 | D9: 371.49605 | E9: 146.33539 | F9: 24.940917 | G9: 2.1147563 | H9: 87.772336 | I9: 65.142265 | J9: 9.5888915 | K9: 64.445818 | L9: 89.646846 | M9: 9.9142919 | N9: 102.49616 | O9: #N/A | P9: 22.252764 | Q9: 0.72824868 | R9: 30.033051 | S9: 4.7166147 | T9: 42.2 | U9: 46.468438 | V9: 38.8
A10: 43082 | B10: 81.022106 | C10: 44.4 | D10: 368.99258 | E10: 143.53337 | F10: 24.185131 | G10: 2.1011378 | H10: 90.046572 | I10: 64.059234 | J10: 9.6252131 | K10: 63.473848 | L10: 90.270631 | M10: 9.6473687 | N10: 104.6315 | O10: #N/A | P10: 21.694895 | Q10: 0.71774509 | R10: 29.014982 | S10: 4.6205082 | T10: 42.6 | U10: 45.693964 | V10: 38.9
A11: 43083 | B11: 82.734354 | C11: 44.2 | D11: 372.42872 | E11: 141.99226 | F11: 24.017179 | G11: 2.1322658 | H11: 91.56273 | I11: 64.259795 | J11: 9.6252131 | K11: 64.065482 | L11: 88.265607 | M11: 9.6855006 | N11: 103.99881 | O11: #N/A | P11: 21.508939 | Q11: 0.7124933 | R11: 28.472012 | S11: 4.5244016 | T11: 43.15 | U11: 46.961285 | V11: 38.2
A12: 43084 | B12: 82.442908 | C12: 44.7 | D12: 362.0712 | E12: 140.69633 | F12: 23.891215 | G12: 2.1789577 | H12: 92.221929 | I12: 62.775643 | J12: 9.55257 | K12: 63.642886 | L12: 89.557733 | M12: 9.7617643 | N12: 104.78967 | O12: #N/A | P12: 21.570925 | Q12: 0.7142439 | R12: 28.200526 | S12: 4.54658 | T12: 42.9 | U12: 46.398031 | V12: 38.9
A13: 43087 | B13: 83.171524 | C13: 44.35 | D13: 364.86921 | E13: 142.93794 | F13: 23.723263 | G13: 2.2295407 | H13: 93.540327 | I13: 63.457551 | J13: 9.5888915 | K13: 63.896444 | L13: 89.112173 | M13: 9.7236325 | N13: 106.21323 | O13: #N/A | P13: 22.004822 | Q13: 0.72474749 | R13: 28.743497 | S13: 4.54658 | T13: 42.65 | U13: 45.693964 | V13: 38.9
... A989: 44553 | B989: 151.16223 | C989: 161.7 | D989: 817.25 | E989: 226.10426 | F989: 58.698558 | G989: 8.9632786 | H989: 150.33088 | I989: 180.3155 | J989: 100.49842 | K989: 232.27556 | L989: 75.411949 | M989: 85.787258 | N989: 204.94065 | O989: #N/A | P989: 65.773427 | Q989: 2.3593673 | R989: 47.838481 | S989: 22.508316 | T989: 52.25 | U989: 75.636846 | V989: 36.05
A990: 44557 | B990: 151.80708 | C990: 158.95 | D990: 819.1 | E990: 225.83995 | F990: 58.081606 | G990: 8.8047103 | H990: 153.29069 | I990: 178.39725 | J990: 101.27748 | K990: 229.14727 | L990: 75.881221 | M990: 85.050096 | N990: 206.88322 | O990: #N/A | P990: 62.042994 | Q990: 2.4266647 | R990: 47.317554 | S990: #N/A | T990: 53.8 | U990: 76.043495 | V990: 36.1
A991: 44558 | B991: 146.53443 | C991: 161.35 | D991: 801.6 | E991: 214.88967 | F991: 55.613799 | G991: 8.5209566 | H991: 145.71908 | I991: 178.58907 | J991: 99.719361 | K991: 230.01624 | L991: 73.441008 | M991: 80.719267 | N991: 200.8127 | O991: #N/A | P991: 62.53384 | Q991: 2.4306234 | R991: 46.102057 | S991: 22.204149 | T991: 51.85 | U991: 74.091577 | V991: 34.3
A992: 44559 | B992: 149.45525 | C992: 163.75 | D992: 806.2 | E992: 217.53284 | F992: 58.125674 | G992: 8.5835494 | H992: 153.97902 | I992: 178.7809 | J992: 99.914125 | K992: 230.05968 | L992: 75.928148 | M992: 84.565976 | N992: 202.31819 | O992: #N/A | P992: 62.042994 | Q992: 2.4741687 | R992: 47.230733 | S992: 22.595221 | T992: 52.1 | U992: 76.124825 | V992: 37
A993: 44560 | B993: 148.20347 | C993: 166.2 | D993: 778.45 | E993: 217.19301 | F993: 56.935838 | G993: 8.6795249 | H993: 154.39201 | I993: 173.69754 | J993: 97.187424 | K993: 236.53351 | L993: 76.491274 | M993: 85.764839 | N993: 196.49049 | O993: #N/A | P993: 64.366334 | Q993: 2.5375075 | R993: 46.970269 | S993: 23.029744 | T993: 57.05 | U993: 76.450145 | V993: 38.6
A994: 44564 | B994: 152.67954 | C994: 167.3 | D994: 830.8 | E994: 222.21503 | F994: 60.285005 | G994: 8.896513 | H994: 153.91018 | I994: 178.20543 | J994: 99.524596 | K994: 238.09765 | L994: 77.899089 | M994: 86.594822 | N994: 202.12393 | O994: #N/A | P994: 65.577088 | Q994: 2.6245982 | R994: 47.230733 | S994: 23.160101 | T994: 59.55 | U994: 78.483394 | V994: 39.35
A995: 44565 | B995: 149.64492 | C995: 166.3 | D995: 843.9 | E995: 219.23202 | F995: 58.390082 | G995: 8.8589574 | H995: 150.22763 | I995: 179.30842 | J995: 101.667 | K995: 235.23005 | L995: 76.350492 | M995: 85.211518 | N995: 205.81481 | O995: #N/A | P995: 65.118965 | Q995: 2.6325155 | R995: 47.05709 | S995: 22.942839 | T995: 58.7 | U995: 78.727384 | V995: 38.9
A996: 44566 | B996: 146.53443 | C996: 158.55 | D996: 828.4 | E996: 212.47306 | F996: 56.935838 | G996: 9.0175256 | H996: 146.30416 | I996: 176.38309 | J996: 100.30365 | K996: 237.22868 | L996: 76.491274 | M996: 83.828214 | N996: 204.35788 | O996: #N/A | P996: 63.646425 | Q996: 2.5850115 | R996: 46.622984 | S996: 22.812482 | T996: 56.3 | U996: 77.344775 | V996: 38.15
A997: 44567 | B997: 148.0138 | C997: 159.25 | D997: 829 | E997: 218.55235 | F997: 56.274819 | G997: 8.9215501 | H997: 149.64255 | I997: 175.90353 | J997: 99.524596 | K997: 237.66317 | L997: 76.444347 | M997: 82.26047 | N997: 202.12393 | O997: #N/A | P997: 63.090133 | Q997: 2.5414661 | R997: 46.362521 | S997: #N/A | T997: 56.25 | U997: 75.962166 | V997: 38
A998: 44568 | B998: 150.21391 | C998: 162.1 | D998: 834.4 | E998: 221.23328 | F998: 57.729062 | G998: 8.9090315 | H998: 152.0517 | I998: 177.77382 | J998: 99.524596 | K998: 238.61903 | L998: 77.664453 | M998: 82.906011 | N998: 203.53229 | O998: #N/A | P998: 64.039103 | Q998: 2.5295901 | R998: 45.928415 | S998: #N/A | T998: 54.8 | U998: 74.498227 | V998: 37.4
A999: 44571 | B999: 149.30352 | C999: 158.15 | D999: 821.6 | E999: 219.79842 | F999: 56.451091 | G999: 8.7713275 | H999: 150.05555 | I999: 187.07733 | J999: 99.329832 | K999: 235.09971 | L999: 76.632055 | M999: 82.076029 | N999: 204.16362 | O999: #N/A | P999: 64.595395 | Q999: 2.5018794 | R999: 45.407488 | S999: 22.899387 | T999: 53.45 | U999: 73.440937 | V999: 35.75
A1000: 44572 | B1000: 151.80708 | C1000: 158.65 | D1000: 849.15 | E1000: 223.00798 | F1000: 59.227374 | G1000: 8.842266 | H1000: 151.12245 | I1000: 194.60646 | J1000: 98.550775 | K1000: 235.14316 | L1000: 76.819764 | M1000: 82.813791 | N1000: 207.80593 | O1000: #N/A | P1000: 64.922626 | Q1000: 2.4900034 | R1000: 45.841594 | S1000: 22.942839 | T1000: 53.25 | U1000: 73.928917 | V1000: 35.45
A1001: 44573 | B1001: 151.50362 | C1001: 161.95 | D1001: 853.3 | E1001: 223.61213 | F1001: 61.827385 | G1001: 8.9215501 | H1001: 153.63485 | I1001: 197.14814 | J1001: 98.745539 | K1001: 235.05626 | L1001: 76.39742 | M1001: 81.983809 | N1001: 206.88322 | O1001: #N/A | P1001: 65.80615 | Q1001: 2.5137554 | R1001: 45.754772 | S1001: 22.986292 | T1001: 53.8 | U1001: 73.278277 | V1001: 35.65
A1002: 44574 | B1002: 150.70703 | C1002: 162.25 | D1002: 879.35 | E1002: 227.35033 | F1002: 61.959589 | G1002: 8.8756488 | H1002: 156.80116 | I1002: 192.01682 | J1002: 97.771717 | K1002: 233.53556 | L1002: 77.289036 | M1002: 83.735994 | N1002: 203.67798 | O1002: #N/A | P1002: 66.984181 | Q1002: 2.5295901 | R1002: 45.667951 | S1002: 22.942839 | T1002: 54.05 | U1002: 73.196948 | V1002: 35.5
A1003: 44575 | B1003: 149.98631 | C1003: 161.45 | D1003: 897.4 | E1003: 230.48437 | F1003: 62.400269 | G1003: 8.9215501 | H1003: 153.84135 | I1003: 189.90675 | J1003: 98.161246 | K1003: 233.23142 | L1003: 75.646585 | M1003: 83.828214 | N1003: 205.2806 | O1003: #N/A | P1003: 66.591504 | Q1003: 2.5493835 | R1003: 45.841594 | S1003: 22.76903 | T1003: 52.6 | U1003: 72.220988 | V1003: 35.9
A1004: 44578 | B1004: 148.65866 | C1004: 160.35 | D1004: 886.1 | E1004: 226.0665 | F1004: 63.061289 | G1004: 8.8547845 | H1004: 153.56602 | I1004: 188.70784 | J1004: 96.99266 | K1004: 240.96525 | L1004: 75.130386 | M1004: 83.459333 | N1004: 206.78609 | O1004: #N/A | P1004: 66.100658 | Q1004: 2.5454248 | R1004: 45.407488 | S1004: 22.942839 | T1004: 53.05 | U1004: 71.326359 | V1004: 35.8
A1005: 44579 | B1005: 143.34807 | C1005: 156.85 | D1005: 880.3 | E1005: 223.12126 | F1005: 59.359578 | G1005: 8.9173772 | H1005: 148.61006 | I1005: 183.43266 | J1005: 95.629309 | K1005: 231.84107 | L1005: 73.487936 | M1005: 82.629351 | N1005: 204.69783 | O1005: #N/A | P1005: 66.624227 | Q1005: 2.5097968 | R1005: 44.973382 | S1005: 22.551768 | T1005: 51.85 | U1005: 68.317151 | V1005: 35.15
A1006: 44580 | B1006: 144.94125 | C1006: 160.15 | D1006: 866.3 | E1006: 226.55738 | F1006: 58.21381 | G1006: 8.9215501 | H1006: 148.67889 | I1006: 187.55689 | J1006: 95.824073 | K1006: 229.40796 | L1006: 72.314757 | M1006: 82.629351 | N1006: 204.45501 | O1006: #N/A | P1006: 68.293105 | Q1006: 2.5493835 | R1006: 44.278812 | S1006: 22.464863 | T1006: 51.8 | U1006: 70.10641 | V1006: 35.6
A1007: 44581 | B1007: 148.469 | C1007: 164.85 | D1007: 877.35 | E1007: 233.80721 | F1007: 59.888394 | G1007: 8.9173772 | H1007: 152.87769 | I1007: 190.62609 | J1007: 96.99266 | K1007: 232.18866 | L1007: 74.191843 | M1007: 84.934857 | N1007: 215.62476 | O1007: #N/A | P1007: 71.336353 | Q1007: 2.5216728 | R1007: 44.799739 | S1007: 22.421411 | T1007: 52.55 | U1007: 69.94375 | V1007: 35.5
A1008: 44582 | B1008: 143.68946 | C1008: 166.25 | D1008: 851.65 | E1008: 225.19803 | F1008: 57.905334 | G1008: 8.8839945 | H1008: 151.15687 | I1008: 187.94054 | J1008: 96.603131 | K1008: 226.7576 | L1008: 73.206373 | M1008: 82.906011 | N1008: 213.87645 | O1008: #N/A | P1008: 69.536583 | Q1008: 2.4702101 | R1008: 42.67262 | S1008: 21.856531 | T1008: 53.3 | U1008: 67.259862 | V1008: 35
A1009: 44585 | B1009: 137.73401 | C1009: 163.8 | D1009: 826.2 | E1009: 211.07596 | F1009: 54.644303 | G1009: 8.8380931 | H1009: 143.51643 | I1009: 185.01521 | J1009: 94.460723 | K1009: 223.41207 | L1009: 70.860015 | M1009: 78.479439 | N1009: 211.6425 | O1009: #N/A | P1009: 68.358551 | Q1009: 2.35145 | R1009: 40.024573 | S1009: 21.508912 | T1009: 53.35 | U1009: 62.461395 | V1009: 33.35
A1010: 44586 | B1010: 150.13804 | C1010: 176.05 | D1010: 889.6 | E1010: 222.02623 | F1010: 58.125674 | G1010: 8.9632786 | H1010: 152.60236 | I1010: 193.45551 | J1010: 96.603131 | K1010: 231.40659 | L1010: 75.740439 | M1010: 80.508285 | N1010: 213.92502 | O1010: #N/A | P1010: 73.20157 | Q1010: 2.4306234 | R1010: 42.67262 | S1010: 22.073792 | T1010: 54.4 | U1010: 65.714593 | V1010: 35.3
... A1740: 45677 | B1740: 7665.039 | C1740: 4045 | D1740: 50950 | E1740: 11600.727 | F1740: 1431.2175 | G1740: 208.23562 | H1740: 8428.9626 | I1740: 6416.5463 | J1740: 793 | K1740: 2570 | L1740: 4041.1328 | M1740: 809.53477 | N1740: 2984.3618 | O1740: #N/A | P1740: 1318.519 | Q1740: 105.93867 | R1740: 2222.6227 | S1740: 450.56105 | T1740: 2005 | U1740: 3280.2766 | V1740: 2545
A1741: 45678 | B1741: 7904.5715 | C1741: 4210 | D1741: 51550 | E1741: 12026.009 | F1741: 1556.6814 | G1741: 218.9649 | H1741: 8886.9525 | I1741: 6723.4663 | J1741: 782 | K1741: 2700 | L1741: 4100.1275 | M1741: 800.56209 | N1741: 2974.3973 | O1741: 2837.2342 | P1741: 1378.2428 | Q1741: 111.47939 | R1741: 2300.7618 | S1741: 453.03395 | T1741: 2130 | U1741: 3340.7823 | V1741: 2575
A1742: 45679 | B1742: 8153.6853 | C1742: 4235 | D1742: 51800 | E1742: 12380.41 | F1742: 1612.4431 | G1742: 226.40971 | H1742: 9228.0088 | I1742: 7030.3863 | J1742: 808 | K1742: 2805 | L1742: 4178.787 | M1742: 835.45583 | N1742: 3064.0776 | O1742: 3052.4 | P1742: 1392.0253 | Q1742: 109.59555 | R1742: 2305.1029 | S1742: 454.51768 | T1742: 2230 | U1742: 3392.6444 | V1742: 2735
A1743: 45680 | B1743: 8000.3845 | C1743: 4175 | D1743: 50050 | E1743: 11955.128 | F1743: 1552.0345 | G1743: 227.28556 | H1743: 8916.1859 | I1743: 6733.0575 | J1743: 827 | K1743: 2720 | L1743: 4026.3842 | M1743: 868.35564 | N1743: 3024.2197 | O1743: 3079.823 | P1743: 1378.2428 | Q1743: 106.71437 | R1743: 2331.1492 | S1743: 453.03395 | T1743: 2170 | U1743: 3332.1387 | V1743: 2680
A1744: 45681 | B1744: 7894.9902 | C1744: 4040 | D1744: 48100 | E1744: 11482.594 | F1744: 1505.5664 | G1744: 227.72349 | H1744: 8653.0854 | I1744: 6474.0938 | J1744: 816 | K1744: 2745 | L1744: 3878.8976 | M1744: 873.34046 | N1744: 2904.6459 | O1744: 3048.181 | P1744: 1437.9667 | Q1744: 103.05749 | R1744: 2335.4903 | S1744: 446.10985 | T1744: 2135 | U1744: 3340.7823 | V1744: 2670
...

Sheet INPUT W A VALOR
A1: ticker | B1: weight
A2: ALUA | B2: 0.023446268
A3: BBAR | B3: 0.050522471
A4: BMA | B4: 0.080197451
A5: BYMA | B5: 0.057434067
A6: CEPU | B6: 0.077996941
A7: COME | B7: 0.012532313
A8: CRES | B8: 0.02521563
A9: ECOG | B9: 0.011326389
A10: EDN | B10: 0.01223914
A11: GGAL | B11: 0.14061638
A12: LOMA | B12: 0.030277721
A13: METR | B13: 0.0082026787
... A21: YPFD | B21: 0.17393153

Sheet resultados
A1: Ticker | B1: Benchmark (%) | C1: Black-Litterman (%) | D1: EP-Shannon (%) | E1: q-Tsallis-EP (q=2.0) (%)
A2: ALUA | B2: 2.6768 | C2: 2.9216 | D2: 15.7675 | E2: 15.7824
A3: BBAR | B3: 5.2048 | C3: 0 | D3: 0 | E3: 0
A4: BMA | B4: 8.0094 | C4: 0 | D4: 0 | E4: 0
A5: BYMA | B5: 4.7222 | C5: 4.4471 | D5: 22.5765 | E5: 22.5607
A6: CEPU | B6: 6.2323 | C6: 3.4694 | D6: 0 | E6: 0
A7: COME | B7: 1.3602 | C7: 1.2274 | D7: 0 | E7: 0
A8: CRES | B8: 2.6799 | C8: 2.7282 | D8: 2.1515 | E8: 2.1393
A9: EDN | B9: 1.228 | C9: 1.0369 | D9: 0 | E9: 0
A10: GGAL | B10: 15.0428 | C10: 7.8439 | D10: 0 | E10: 0
A11: LOMA | B11: 3.4749 | C11: 3.4029 | D11: 0 | E11: 0
A12: METR | B12: 0.8689 | C12: 0.2774 | D12: 0 | E12: 0
A13: PAMP | B13: 14.6787 | C13: 27.0455 | D13: 6.2464 | E13: 6.0501
... A22: TOTAL | B22: 100 | C22: 100 | D22: 100 | E22: 100
